Python 3.6.0 (v3.6.0:41df79263a11, Dec 23 2016, 07:18:10) [MSC v.1900 32 bit (Intel)] on win32
Type "copyright", "credits" or "license()" for more information.
>>> 
 RESTART: C:/Users/kevin/AppData/Local/Programs/Python/Python36-32/function and call.py 
Traceback (most recent call last):
  File "C:/Users/kevin/AppData/Local/Programs/Python/Python36-32/function and call.py", line 2, in <module>
    x=sum_two_numbers(1,2)
NameError: name 'sum_two_numbers' is not defined
>>> 
>>> 
 RESTART: C:/Users/kevin/AppData/Local/Programs/Python/Python36-32/function and call.py 
Traceback (most recent call last):
  File "C:/Users/kevin/AppData/Local/Programs/Python/Python36-32/function and call.py", line 2, in <module>
    x=sum_two_numbers(1,2)
NameError: name 'sum_two_numbers' is not defined
>>> 
 RESTART: C:/Users/kevin/AppData/Local/Programs/Python/Python36-32/function and call.py 
>>> 
>>> 
 RESTART: C:/Users/kevin/AppData/Local/Programs/Python/Python36-32/function and call.py 
3
>>> 
 RESTART: C:/Users/kevin/AppData/Local/Programs/Python/Python36-32/classes and object.py 
>>> 
 RESTART: C:/Users/kevin/AppData/Local/Programs/Python/Python36-32/classes and object.py 
>>> 
 RESTART: C:/Users/kevin/AppData/Local/Programs/Python/Python36-32/classes and object.py 
Traceback (most recent call last):
  File "C:/Users/kevin/AppData/Local/Programs/Python/Python36-32/classes and object.py", line 1, in <module>
    class MyClass:
  File "C:/Users/kevin/AppData/Local/Programs/Python/Python36-32/classes and object.py", line 5, in MyClass
    myobjectx = MyClass()
NameError: name 'MyClass' is not defined
>>> 
 RESTART: C:/Users/kevin/AppData/Local/Programs/Python/Python36-32/classes and object.py 
>>> 
 RESTART: C:/Users/kevin/AppData/Local/Programs/Python/Python36-32/classes and object.py 
blah
>>> 
 RESTART: C:/Users/kevin/AppData/Local/Programs/Python/Python36-32/classes and object.py 
This is a message inside the class.
blah
>>> 
 RESTART: C:/Users/kevin/AppData/Local/Programs/Python/Python36-32/dictionary.py 
{'John': 932568752, 'Jack': 932568752, 'Jill': 932568752}
>>> 
 RESTART: C:/Users/kevin/AppData/Local/Programs/Python/Python36-32/dictionary.py 
{'John': 932568752, 'Jack': 932568752, 'Jill': 932568752}
>>> 
>>> 
 RESTART: C:/Users/kevin/AppData/Local/Programs/Python/Python36-32/dictionary.py 
{'John': 932568752, 'Jack': 932568752, 'Jill': 932568752}
{'Jack': 932568752, 'Jill': 932568752}
>>> 
 RESTART: C:/Users/kevin/AppData/Local/Programs/Python/Python36-32/dictionary.py 
{'John': 932568752, 'Jack': 932568752, 'Jill': 932568752, 'kelvin': 9033345789}
{'Jack': 932568752, 'Jill': 932568752, 'kelvin': 9033345789}
>>> 
 RESTART: C:/Users/kevin/AppData/Local/Programs/Python/Python36-32/dictionary.py 
Traceback (most recent call last):
  File "C:/Users/kevin/AppData/Local/Programs/Python/Python36-32/dictionary.py", line 6, in <module>
    phonebook.pop()
TypeError: pop expected at least 1 arguments, got 0
>>> 
 RESTART: C:/Users/kevin/AppData/Local/Programs/Python/Python36-32/dictionary.py 
Traceback (most recent call last):
  File "C:/Users/kevin/AppData/Local/Programs/Python/Python36-32/dictionary.py", line 6, in <module>
    phonebook.pop("")
KeyError: ''
>>> 
>>> 
 RESTART: C:/Users/kevin/AppData/Local/Programs/Python/Python36-32/dictionary.py 
{'John': 932568752, 'Jack': 932568752, 'Jill': 932568752}
{'Jack': 932568752, 'Jill': 932568752}
>>> 
 RESTART: C:/Users/kevin/AppData/Local/Programs/Python/Python36-32/dictionary.py 
{'John': 932568752, 'Jack': 932568752, 'Jill': 932568752, 'kelvin': 9033345789}
{'Jack': 932568752, 'Jill': 932568752, 'kelvin': 9033345789}
{'Jack': 932568752, 'Jill': 932568752}
>>> 
 RESTART: C:/Users/kevin/AppData/Local/Programs/Python/Python36-32/dictionary.py 
{'John': 932568752, 'Jack': 932568752, 'Jill': 932568752, 'kelvin': 9033345789}
{'Jack': 932568752, 'Jill': 932568752, 'kelvin': 9033345789}
{'Jack': 932568752, 'Jill': 932568752}
Traceback (most recent call last):
  File "C:/Users/kevin/AppData/Local/Programs/Python/Python36-32/dictionary.py", line 15, in <module>
    phonebook.push("kelvin")
AttributeError: 'dict' object has no attribute 'push'
>>> 
>>> 
 RESTART: C:/Users/kevin/AppData/Local/Programs/Python/Python36-32/dictionary.py 
{'John': 932568752, 'Jack': 932568752, 'Jill': 932568752, 'kelvin': 9033345789}
{'Jack': 932568752, 'Jill': 932568752, 'kelvin': 9033345789}
{'Jack': 932568752, 'Jill': 932568752}
>>> 
 RESTART: C:/Users/kevin/AppData/Local/Programs/Python/Python36-32/dictionary.py 
{'John': 932568752, 'Jack': 932568752, 'Jill': 932568752, 'kelvin': 9033345789}
{'Jack': 932568752, 'Jill': 932568752, 'kelvin': 9033345789}
{'Jack': 932568752, 'Jill': 932568752}
>>> 
 RESTART: C:/Users/kevin/AppData/Local/Programs/Python/Python36-32/dictionary.py 
{'John': 932568752, 'Jack': 932568752, 'Jill': 932568752, 'kelvin': 9033345789}
{'Jack': 932568752, 'Jill': 932568752, 'kelvin': 9033345789}
{'Jack': 932568752, 'Jill': 932568752}
9033345789
>>> 
